Traceback (most recent call last):
  File "/home/runner/micromamba/envs/api-cookbook-dev/lib/python3.13/site-packages/jupyter_core/utils/__init__.py", line 154, in wrapped
    asyncio.get_running_loop()
    ~~~~~~~~~~~~~~~~~~~~~~~~^^
RuntimeError: no running event loop

During handling of the above exception, another exception occurred:

Traceback (most recent call last):
  File "/home/runner/micromamba/envs/api-cookbook-dev/lib/python3.13/site-packages/jupyter_cache/executors/utils.py", line 58, in single_nb_execution
    executenb(
    ~~~~~~~~~^
        nb,
        ^^^
    ...<4 lines>...
        **kwargs,
        ^^^^^^^^^
    )
    ^
  File "/home/runner/micromamba/envs/api-cookbook-dev/lib/python3.13/site-packages/nbclient/client.py", line 1319, in execute
    return NotebookClient(nb=nb, resources=resources, km=km, **kwargs).execute()
           ~~~~~~~~~~~~~~~~~~~~~~~~~~~~~~~~~~~~~~~~~~~~~~~~~~~~~~~~~~~~~~~~~~~^^
  File "/home/runner/micromamba/envs/api-cookbook-dev/lib/python3.13/site-packages/jupyter_core/utils/__init__.py", line 158, in wrapped
    return loop.run_until_complete(inner)
           ~~~~~~~~~~~~~~~~~~~~~~~^^^^^^^
  File "/home/runner/micromamba/envs/api-cookbook-dev/lib/python3.13/asyncio/base_events.py", line 725, in run_until_complete
    return future.result()
           ~~~~~~~~~~~~~^^
  File "/home/runner/micromamba/envs/api-cookbook-dev/lib/python3.13/site-packages/nbclient/client.py", line 709, in async_execute
    await self.async_execute_cell(
        cell, index, execution_count=self.code_cells_executed + 1
    )
  File "/home/runner/micromamba/envs/api-cookbook-dev/lib/python3.13/site-packages/nbclient/client.py", line 1062, in async_execute_cell
    await self._check_raise_for_error(cell, cell_index, exec_reply)
  File "/home/runner/micromamba/envs/api-cookbook-dev/lib/python3.13/site-packages/nbclient/client.py", line 918, in _check_raise_for_error
    raise CellExecutionError.from_cell_and_msg(cell, exec_reply_content)
nbclient.exceptions.CellExecutionError: An error occurred while executing the following cell:
------------------
plt.plot(ozone['date_local'], ozone['sample_measurement'], '.')
plt.show()
------------------


[31m---------------------------------------------------------------------------[39m
[31mKeyError[39m                                  Traceback (most recent call last)
[36mCell[39m[36m [39m[32mIn[17][39m[32m, line 1[39m
[32m----> [39m[32m1[39m plt.plot([43mozone[49m[43m[[49m[33;43m'[39;49m[33;43mdate_local[39;49m[33;43m'[39;49m[43m][49m, ozone[[33m'[39m[33msample_measurement[39m[33m'[39m], [33m'[39m[33m.[39m[33m'[39m)
[32m      2[39m plt.show()

[36mFile [39m[32m~/micromamba/envs/api-cookbook-dev/lib/python3.13/site-packages/pandas/core/frame.py:4107[39m, in [36mDataFrame.__getitem__[39m[34m(self, key)[39m
[32m   4105[39m [38;5;28;01mif[39;00m [38;5;28mself[39m.columns.nlevels > [32m1[39m:
[32m   4106[39m     [38;5;28;01mreturn[39;00m [38;5;28mself[39m._getitem_multilevel(key)
[32m-> [39m[32m4107[39m indexer = [38;5;28;43mself[39;49m[43m.[49m[43mcolumns[49m[43m.[49m[43mget_loc[49m[43m([49m[43mkey[49m[43m)[49m
[32m   4108[39m [38;5;28;01mif[39;00m is_integer(indexer):
[32m   4109[39m     indexer = [indexer]

[36mFile [39m[32m~/micromamba/envs/api-cookbook-dev/lib/python3.13/site-packages/pandas/core/indexes/range.py:417[39m, in [36mRangeIndex.get_loc[39m[34m(self, key)[39m
[32m    415[39m         [38;5;28;01mraise[39;00m [38;5;167;01mKeyError[39;00m(key) [38;5;28;01mfrom[39;00m[38;5;250m [39m[34;01merr[39;00m
[32m    416[39m [38;5;28;01mif[39;00m [38;5;28misinstance[39m(key, Hashable):
[32m--> [39m[32m417[39m     [38;5;28;01mraise[39;00m [38;5;167;01mKeyError[39;00m(key)
[32m    418[39m [38;5;28mself[39m._check_indexing_error(key)
[32m    419[39m [38;5;28;01mraise[39;00m [38;5;167;01mKeyError[39;00m(key)

[31mKeyError[39m: 'date_local'

