Traceback (most recent call last):
  File "/home/runner/micromamba/envs/api-cookbook-dev/lib/python3.13/site-packages/jupyter_core/utils/__init__.py", line 154, in wrapped
    asyncio.get_running_loop()
    ~~~~~~~~~~~~~~~~~~~~~~~~^^
RuntimeError: no running event loop

During handling of the above exception, another exception occurred:

Traceback (most recent call last):
  File "/home/runner/micromamba/envs/api-cookbook-dev/lib/python3.13/site-packages/jupyter_cache/executors/utils.py", line 58, in single_nb_execution
    executenb(
    ~~~~~~~~~^
        nb,
        ^^^
    ...<4 lines>...
        **kwargs,
        ^^^^^^^^^
    )
    ^
  File "/home/runner/micromamba/envs/api-cookbook-dev/lib/python3.13/site-packages/nbclient/client.py", line 1319, in execute
    return NotebookClient(nb=nb, resources=resources, km=km, **kwargs).execute()
           ~~~~~~~~~~~~~~~~~~~~~~~~~~~~~~~~~~~~~~~~~~~~~~~~~~~~~~~~~~~~~~~~~~~^^
  File "/home/runner/micromamba/envs/api-cookbook-dev/lib/python3.13/site-packages/jupyter_core/utils/__init__.py", line 158, in wrapped
    return loop.run_until_complete(inner)
           ~~~~~~~~~~~~~~~~~~~~~~~^^^^^^^
  File "/home/runner/micromamba/envs/api-cookbook-dev/lib/python3.13/asyncio/base_events.py", line 725, in run_until_complete
    return future.result()
           ~~~~~~~~~~~~~^^
  File "/home/runner/micromamba/envs/api-cookbook-dev/lib/python3.13/site-packages/nbclient/client.py", line 709, in async_execute
    await self.async_execute_cell(
        cell, index, execution_count=self.code_cells_executed + 1
    )
  File "/home/runner/micromamba/envs/api-cookbook-dev/lib/python3.13/site-packages/nbclient/client.py", line 1062, in async_execute_cell
    await self._check_raise_for_error(cell, cell_index, exec_reply)
  File "/home/runner/micromamba/envs/api-cookbook-dev/lib/python3.13/site-packages/nbclient/client.py", line 918, in _check_raise_for_error
    raise CellExecutionError.from_cell_and_msg(cell, exec_reply_content)
nbclient.exceptions.CellExecutionError: An error occurred while executing the following cell:
------------------
# convert Longitude from 0-360 to -180-180
sla_ds.coords['Longitude'] = (sla_ds.coords['Longitude'] + 180) % 360 - 180
sla_ds = sla_ds.sortby(sla_ds.Longitude)
sla_ds
------------------


[31m---------------------------------------------------------------------------[39m
[31mNameError[39m                                 Traceback (most recent call last)
[36mCell[39m[36m [39m[32mIn[7][39m[32m, line 2[39m
[32m      1[39m [38;5;66;03m# convert Longitude from 0-360 to -180-180[39;00m
[32m----> [39m[32m2[39m sla_ds.coords[[33m'[39m[33mLongitude[39m[33m'[39m] = ([43msla_ds[49m.coords[[33m'[39m[33mLongitude[39m[33m'[39m] + [32m180[39m) % [32m360[39m - [32m180[39m
[32m      3[39m sla_ds = sla_ds.sortby(sla_ds.Longitude)
[32m      4[39m sla_ds

[31mNameError[39m: name 'sla_ds' is not defined

